Workbook
Name List_Factions: Price_List!$AA$2:$AA$3
Name Series_天族: Price_List!$AB$2:$AB$6
Name Series_魔族: Price_List!$AC$2:$AC$6
Name 白龍王系列: Price_List!$AF$2:$AF$20
Name 其他天族系列: Price_List!$AH$2:$AH$20
Name 其他魔族系列: Price_List!#REF!
Name 真龍王系列: Price_List!$AG$2:$AG$20
Name 乾龍王系列: Price_List!$AL$2:$AL$20
Name 黑龍王系列: Price_List!$AK$2:$AK$20
Name 暗龍王系列: Price_List!$AJ$2:$AJ$20
Name 鳴龍王系列: Price_List!$AE$2:$AE$20
Name 應龍王系列: Price_List!$AD$2:$AD$20
Name 夔龍王系列: Price_List!$AI$2:$AI$20

Sheet Dashboard
A1: 【浮光棲地裝備升級暨製造指揮部】 | E1: 神一 製 | Z1: 標準
Z2: 樂觀
A3: 管道 A (零售) | E3: 管道 B (大盤) | I3: 物資需求清單 (HUD) | Z3: 悲觀
A4: 1 TWD = | B4: 37000 | C4: 遊戲幣 | E4: 總價 | F4: 10000000
E5: TWD | F5: 270 | I5: =HYPERLINK("#Data_Recipes!A1", ">>> 查看配方表 <<<") -> >>> 查看配方表 <<<
A6: 最佳匯率： | B6: =IF((B4)>(F4/F5), "管道 A (零售) 勝", "管道 B (大盤) 勝") -> 管道 B (大盤) 勝
A8: 戰略配置 (Configuration) | I8: ⚠️ 更新價格
A9: 1. 採購策略 | B9: 標準
A10: 2. 陣營選擇 | B10: 魔族
A11: 3. 裝備系列 | B11: 暗龍王系列
A12: 4. 目標部位 | B12: 臂甲
A13: 5. 製作數量 | B13: 1 | C13: (戒指/耳環請填 2)
A15: 【核心決策矩陣】
A16: 拍賣場單價： | B16: 0 | E16: 自造總成本 (Net)： | F16: =SUMIFS(Data_Recipes!F:F, Data_Recipes!A:A, B11, Data_Recipes!B:B, B12) * B13 -> 78307795
A18: 交易渠道 | B18: 耗損 | C18: 自造含稅 (Gross) | D18: 自造 TWD | E18: 直購 TWD (總價) | F18: 戰術建議
A19: 本服拍賣 | B19: 0.12 | C19: =$F$16/(1-B19) -> 88986131 | D19: =C19/MAX($B$4, $F$4/$F$5) -> 2402.6255 | E19: =($B$16 * $B$13)/MAX($B$4, $F$4/$F$5) -> 0 | F19: =IF(C19<($B$16*$B$13), "自造省 $"&TEXT(((($B$16*$B$13)-C19)/MAX($B$4, $F$4/$F$5)),"0"), "直購省 $"&TEXT(((C19-($B$16*$B$13))/MAX($B$4, $F$4/$F$5)),"0")) -> 直購省 $2403
A20: 個人交易 | B20: 0.2 | C20: =$F$16/(1-B20) -> 97884744 | D20: =C20/MAX($B$4, $F$4/$F$5) -> 2642.8881 | E20: =($B$16 * $B$13)/MAX($B$4, $F$4/$F$5) -> 0 | F20: =IF(C20<($B$16*$B$13), "自造省 $"&TEXT(((($B$16*$B$13)-C20)/MAX($B$4, $F$4/$F$5)),"0"), "直購省 $"&TEXT(((C20-($B$16*$B$13))/MAX($B$4, $F$4/$F$5)),"0")) -> 直購省 $2643
A21: 跨服拍賣 | B21: 0.22 | C21: =$F$16/(1-B21) -> 1.0039461e+08 | D21: =C21/MAX($B$4, $F$4/$F$5) -> 2710.6544 | E21: =($B$16 * $B$13)/MAX($B$4, $F$4/$F$5) -> 0 | F21: =IF(C21<($B$16*$B$13), "自造省 $"&TEXT(((($B$16*$B$13)-C21)/MAX($B$4, $F$4/$F$5)),"0"), "直購省 $"&TEXT(((C21-($B$16*$B$13))/MAX($B$4, $F$4/$F$5)),"0")) -> 直購省 $2711

Sheet Price_List
A1: 材料名稱 | B1: 目前市價 | C1: 低價(0.8) | D1: 高價(1.2) | E1: 備註 | AA1: Faction_List | AB1: Series_天族 | AC1: Series_魔族 | AD1: 應龍王系列 | AE1: 鳴龍王系列 | AF1: 白龍王系列 | AG1: 真龍王系列 | AH1: 其他天族系列 | AI1: 夔龍王系列 | AJ1: 暗龍王系列 | AK1: 黑龍王系列 | AL1: 乾龍王系列
A2: 強化的厚實龍族鱗片 | B2: 57999 | C2: =IF(B2="", "", B2*0.8) -> 46399.2 | D2: =IF(B2="", "", B2*1.2) -> 69598.8 | AA2: 魔族 | AB2: 應龍王系列 | AC2: 夔龍王系列 | AD2: 長劍 | AE2: 長劍 | AF2: 長劍 | AG2: 長劍 | AH2: 長劍 | AI2: 長劍 | AJ2: 長劍 | AK2: 長劍 | AL2: 長劍
A3: 強化的堅固龍族鱗片 | B3: 11900 | C3: =IF(B3="", "", B3*0.8) -> 9520 | D3: =IF(B3="", "", B3*1.2) -> 14280 | AA3: 天族 | AB3: 鳴龍王系列 | AC3: 暗龍王系列 | AD3: 巨劍 | AE3: 巨劍 | AF3: 巨劍 | AG3: 巨劍 | AH3: 巨劍 | AI3: 巨劍 | AJ3: 巨劍 | AK3: 巨劍 | AL3: 巨劍
A4: 強化的堅硬龍族鱗片 | B4: 5984 | C4: =IF(B4="", "", B4*0.8) -> 4787.2 | D4: =IF(B4="", "", B4*1.2) -> 7180.8 | AB4: 白龍王系列 | AC4: 黑龍王系列 | AD4: 短劍 | AE4: 短劍 | AF4: 短劍 | AG4: 短劍 | AH4: 短劍 | AI4: 短劍 | AJ4: 短劍 | AK4: 短劍 | AL4: 短劍
A5: 強化的強固龍族鱗片 | B5: 1222222 | C5: =IF(B5="", "", B5*0.8) -> 977777.6 | D5: =IF(B5="", "", B5*1.2) -> 1466666.4 | AB5: 真龍王系列 | AC5: 乾龍王系列 | AD5: 弓 | AE5: 弓 | AF5: 弓 | AG5: 弓 | AH5: 弓 | AI5: 弓 | AJ5: 弓 | AK5: 弓 | AL5: 弓
A6: 提煉的厚實龍族角 | B6: 4665 | C6: =IF(B6="", "", B6*0.8) -> 3732 | D6: =IF(B6="", "", B6*1.2) -> 5598 | AD6: 法書 | AE6: 法書 | AF6: 法書 | AG6: 法書 | AH6: 法書 | AI6: 法書 | AJ6: 法書 | AK6: 法書 | AL6: 法書
A7: 提煉的堅固龍族角 | B7: 11900 | C7: =IF(B7="", "", B7*0.8) -> 9520 | D7: =IF(B7="", "", B7*1.2) -> 14280 | AD7: 法珠 | AE7: 法珠 | AF7: 法珠 | AG7: 法珠 | AH7: 法珠 | AI7: 法珠 | AJ7: 法珠 | AK7: 法珠 | AL7: 法珠
A8: 提煉的堅硬龍族角 | B8: 2500 | C8: =IF(B8="", "", B8*0.8) -> 2000 | D8: =IF(B8="", "", B8*1.2) -> 3000 | AD8: 釘錘 | AE8: 釘錘 | AF8: 釘錘 | AG8: 釘錘 | AH8: 釘錘 | AI8: 釘錘 | AJ8: 釘錘 | AK8: 釘錘 | AL8: 釘錘
A9: 提煉的強固龍族角 | B9: 2500000 | C9: =IF(B9="", "", B9*0.8) -> 2000000 | D9: =IF(B9="", "", B9*1.2) -> 3000000 | AD9: 法杖 | AE9: 法杖 | AF9: 法杖 | AG9: 法杖 | AH9: 法杖 | AI9: 法杖 | AJ9: 法杖 | AK9: 法杖 | AL9: 法杖
A10: 發狂的憤怒巫蠱 | B10: 6879998 | C10: =IF(B10="", "", B10*0.8) -> 5503998.4 | D10: =IF(B10="", "", B10*1.2) -> 8255997.6 | AD10: 臂甲 | AE10: 臂甲 | AF10: 臂甲 | AG10: 臂甲 | AH10: 臂甲 | AI10: 臂甲 | AJ10: 臂甲 | AK10: 臂甲 | AL10: 臂甲
A11: 達人閃耀的紅寶石項鍊 | B11: 2749000 | C11: =IF(B11="", "", B11*0.8) -> 2199200 | D11: =IF(B11="", "", B11*1.2) -> 3298800 | AD11: 頭盔 | AE11: 頭盔 | AF11: 頭盔 | AG11: 頭盔 | AH11: 頭盔 | AI11: 頭盔 | AJ11: 頭盔 | AK11: 頭盔 | AL11: 頭盔
A12: 達人閃耀的真實法珠 | B12: 2999990 | C12: =IF(B12="", "", B12*0.8) -> 2399992 | D12: =IF(B12="", "", B12*1.2) -> 3599988 | AD12: 肩甲 | AE12: 肩甲 | AF12: 肩甲 | AG12: 肩甲 | AH12: 肩甲 | AI12: 肩甲 | AJ12: 肩甲 | AK12: 肩甲 | AL12: 肩甲
A13: 達人閃耀的真實魔法書 | B13: 2900000 | C13: =IF(B13="", "", B13*0.8) -> 2320000 | D13: =IF(B13="", "", B13*1.2) -> 3480000 | AD13: 胸甲 | AE13: 胸甲 | AF13: 胸甲 | AG13: 胸甲 | AH13: 胸甲 | AI13: 胸甲 | AJ13: 胸甲 | AK13: 胸甲 | AL13: 胸甲
A14: 達人閃耀的菩提弓 | B14: 3300088 | C14: =IF(B14="", "", B14*0.8) -> 2640070.4 | D14: =IF(B14="", "", B14*1.2) -> 3960105.6 | AD14: 腿甲 | AE14: 腿甲 | AF14: 腿甲 | AG14: 腿甲 | AH14: 腿甲 | AI14: 腿甲 | AJ14: 腿甲 | AK14: 腿甲 | AL14: 腿甲
A15: 達人閃耀的菩提法杖 | B15: 3150000 | C15: =IF(B15="", "", B15*0.8) -> 2520000 | D15: =IF(B15="", "", B15*1.2) -> 3780000 | AD15: 手套 | AE15: 手套 | AF15: 手套 | AG15: 手套 | AH15: 手套 | AI15: 手套 | AJ15: 手套 | AK15: 手套 | AL15: 手套
A16: 達人閃耀的奧里哈康手套 | B16: 8222222 | C16: =IF(B16="", "", B16*0.8) -> 6577777.6 | D16: =IF(B16="", "", B16*1.2) -> 9866666.4 | AD16: 鞋子 | AE16: 鞋子 | AF16: 鞋子 | AG16: 鞋子 | AH16: 鞋子 | AI16: 鞋子 | AJ16: 鞋子 | AK16: 鞋子 | AL16: 鞋子
A17: 達人閃耀的奧里哈康巨劍 | B17: 2866664 | C17: =IF(B17="", "", B17*0.8) -> 2293331.2 | D17: =IF(B17="", "", B17*1.2) -> 3439996.8 | AD17: 披風 | AE17: 披風 | AF17: 披風 | AG17: 披風 | AH17: 披風 | AI17: 披風 | AJ17: 披風 | AK17: 披風 | AL17: 披風
... A20: 達人閃耀的奧里哈康長靴 | B20: 10400000 | C20: =IF(B20="", "", B20*0.8) -> 8320000 | D20: =IF(B20="", "", B20*1.2) -> 12480000 | AD20: 戒指 | AE20: 戒指 | AF20: 戒指 | AG20: 戒指 | AH20: 戒指 | AI20: 戒指 | AJ20: 戒指 | AK20: 戒指 | AL20: 戒指
A21: 達人閃耀的奧里哈康長劍 | B21: 3429999 | C21: =IF(B21="", "", B21*0.8) -> 2743999.2 | D21: =IF(B21="", "", B21*1.2) -> 4115998.8
A22: 達人閃耀的奧里哈康胸甲 | B22: 12000000 | C22: =IF(B22="", "", B22*0.8) -> 9600000 | D22: =IF(B22="", "", B22*1.2) -> 14400000
A23: 達人閃耀的奧里哈康釘錘 | B23: 3149990 | C23: =IF(B23="", "", B23*0.8) -> 2519992 | D23: =IF(B23="", "", B23*1.2) -> 3779988
A24: 達人閃耀的奧里哈康短劍 | B24: 3188800 | C24: =IF(B24="", "", B24*0.8) -> 2551040 | D24: =IF(B24="", "", B24*1.2) -> 3826560
A25: 達人閃耀的奧里哈康腿甲 | B25: 10101008 | C25: =IF(B25="", "", B25*0.8) -> 8080806.4 | D25: =IF(B25="", "", B25*1.2) -> 12121210
A26: 達人閃耀的奧里哈康頭盔 | B26: 10500000 | C26: =IF(B26="", "", B26*0.8) -> 8400000 | D26: =IF(B26="", "", B26*1.2) -> 12600000
A27: 達人閃耀的奧里哈康臂甲 | B27: 2599988 | C27: =IF(B27="", "", B27*0.8) -> 2079990.4 | D27: =IF(B27="", "", B27*1.2) -> 3119985.6
A28: 達人閃耀的藍寶石戒指 | B28: 2118888 | C28: =IF(B28="", "", B28*0.8) -> 1695110.4 | D28: =IF(B28="", "", B28*1.2) -> 2542665.6
A29: 達人閃耀的鑽石耳環 | B29: 2350000 | C29: =IF(B29="", "", B29*0.8) -> 1880000 | D29: =IF(B29="", "", B29*1.2) -> 2820000
A30: 達人最上級提煉石 | B30: 560000 | C30: =IF(B30="", "", B30*0.8) -> 448000 | D30: =IF(B30="", "", B30*1.2) -> 672000
A31: 憤怒自我 | B31: 899999 | C31: =IF(B31="", "", B31*0.8) -> 719999.2 | D31: =IF(B31="", "", B31*1.2) -> 1079998.8
A32: 憤怒思念 | B32: 2199999 | C32: =IF(B32="", "", B32*0.8) -> 1759999.2 | D32: =IF(B32="", "", B32*1.2) -> 2639998.8
... A43: 鞣製的強固龍族皮革 | B43: 220000 | C43: =IF(B43="", "", B43*0.8) -> 176000 | D43: =IF(B43="", "", B43*1.2) -> 264000
C44: =IF(B44="", "", B44*0.8) | D44: =IF(B44="", "", B44*1.2)
C45: =IF(B45="", "", B45*0.8) | D45: =IF(B45="", "", B45*1.2)
C46: =IF(B46="", "", B46*0.8) | D46: =IF(B46="", "", B46*1.2)
C47: =IF(B47="", "", B47*0.8) | D47: =IF(B47="", "", B47*1.2)
C48: =IF(B48="", "", B48*0.8) | D48: =IF(B48="", "", B48*1.2)
C49: =IF(B49="", "", B49*0.8) | D49: =IF(B49="", "", B49*1.2)
C50: =IF(B50="", "", B50*0.8) | D50: =IF(B50="", "", B50*1.2)
C51: =IF(B51="", "", B51*0.8) | D51: =IF(B51="", "", B51*1.2)
C52: =IF(B52="", "", B52*0.8) | D52: =IF(B52="", "", B52*1.2)
...

Sheet Data_Recipes
A1: 系列 | B1: 部位 | C1: 材料名稱 | D1: 需求數量 | E1: 單價 | F1: 總價
A2: 乾龍王系列 | B2: 頭盔 | C2: 達人閃耀的奧里哈康頭盔 | D2: 1 | E2: =IF(C2="", "", IFERROR(VLOOKUP(C2, Price_List!A:D, IF(Dashboard!$B$9="樂觀(Snipe)", 3, IF(Dashboard!$B$9="悲觀(Panic)", 4, 2)), 0), 0)) -> 10500000 | F2: =IF(C2="", "", D2*E2) -> 10500000
A3: 乾龍王系列 | B3: 頭盔 | C3: 達人最上級提煉石 | D3: 2 | E3: =IF(C3="", "", IFERROR(VLOOKUP(C3, Price_List!A:D, IF(Dashboard!$B$9="樂觀(Snipe)", 3, IF(Dashboard!$B$9="悲觀(Panic)", 4, 2)), 0), 0)) -> 560000 | F3: =IF(C3="", "", D3*E3) -> 1120000
A4: 乾龍王系列 | B4: 頭盔 | C4: 鞣製的厚實龍族皮革 | D4: 9 | E4: =IF(C4="", "", IFERROR(VLOOKUP(C4, Price_List!A:D, IF(Dashboard!$B$9="樂觀(Snipe)", 3, IF(Dashboard!$B$9="悲觀(Panic)", 4, 2)), 0), 0)) -> 1700 | F4: =IF(C4="", "", D4*E4) -> 15300
A5: 乾龍王系列 | B5: 頭盔 | C5: 憤怒思念 | D5: 4 | E5: =IF(C5="", "", IFERROR(VLOOKUP(C5, Price_List!A:D, IF(Dashboard!$B$9="樂觀(Snipe)", 3, IF(Dashboard!$B$9="悲觀(Panic)", 4, 2)), 0), 0)) -> 2199999 | F5: =IF(C5="", "", D5*E5) -> 8799996
A6: 乾龍王系列 | B6: 頭盔 | C6: 燦爛的奧里哈康礦石 | D6: 5 | E6: =IF(C6="", "", IFERROR(VLOOKUP(C6, Price_List!A:D, IF(Dashboard!$B$9="樂觀(Snipe)", 3, IF(Dashboard!$B$9="悲觀(Panic)", 4, 2)), 0), 0)) -> 205000 | F6: =IF(C6="", "", D6*E6) -> 1025000
A7: 乾龍王系列 | B7: 頭盔 | C7: 燦爛的奧德 | D7: 3 | E7: =IF(C7="", "", IFERROR(VLOOKUP(C7, Price_List!A:D, IF(Dashboard!$B$9="樂觀(Snipe)", 3, IF(Dashboard!$B$9="悲觀(Panic)", 4, 2)), 0), 0)) -> 189998 | F7: =IF(C7="", "", D7*E7) -> 569994
A8: 乾龍王系列 | B8: 腿甲 | C8: 達人閃耀的奧里哈康腿甲 | D8: 1 | E8: =IF(C8="", "", IFERROR(VLOOKUP(C8, Price_List!A:D, IF(Dashboard!$B$9="樂觀(Snipe)", 3, IF(Dashboard!$B$9="悲觀(Panic)", 4, 2)), 0), 0)) -> 10101008 | F8: =IF(C8="", "", D8*E8) -> 10101008
A9: 乾龍王系列 | B9: 腿甲 | C9: 達人最上級提煉石 | D9: 2 | E9: =IF(C9="", "", IFERROR(VLOOKUP(C9, Price_List!A:D, IF(Dashboard!$B$9="樂觀(Snipe)", 3, IF(Dashboard!$B$9="悲觀(Panic)", 4, 2)), 0), 0)) -> 560000 | F9: =IF(C9="", "", D9*E9) -> 1120000
A10: 乾龍王系列 | B10: 腿甲 | C10: 鞣製的厚實龍族皮革 | D10: 11 | E10: =IF(C10="", "", IFERROR(VLOOKUP(C10, Price_List!A:D, IF(Dashboard!$B$9="樂觀(Snipe)", 3, IF(Dashboard!$B$9="悲觀(Panic)", 4, 2)), 0), 0)) -> 1700 | F10: =IF(C10="", "", D10*E10) -> 18700
A11: 乾龍王系列 | B11: 腿甲 | C11: 憤怒思念 | D11: 5 | E11: =IF(C11="", "", IFERROR(VLOOKUP(C11, Price_List!A:D, IF(Dashboard!$B$9="樂觀(Snipe)", 3, IF(Dashboard!$B$9="悲觀(Panic)", 4, 2)), 0), 0)) -> 2199999 | F11: =IF(C11="", "", D11*E11) -> 10999995
A12: 乾龍王系列 | B12: 腿甲 | C12: 燦爛的奧里哈康礦石 | D12: 6 | E12: =IF(C12="", "", IFERROR(VLOOKUP(C12, Price_List!A:D, IF(Dashboard!$B$9="樂觀(Snipe)", 3, IF(Dashboard!$B$9="悲觀(Panic)", 4, 2)), 0), 0)) -> 205000 | F12: =IF(C12="", "", D12*E12) -> 1230000
A13: 乾龍王系列 | B13: 腿甲 | C13: 燦爛的奧德 | D13: 4 | E13: =IF(C13="", "", IFERROR(VLOOKUP(C13, Price_List!A:D, IF(Dashboard!$B$9="樂觀(Snipe)", 3, IF(Dashboard!$B$9="悲觀(Panic)", 4, 2)), 0), 0)) -> 189998 | F13: =IF(C13="", "", D13*E13) -> 759992
... A571: 乾龍王系列 | B571: 戒指 | C571: 燦爛的奧德 | D571: 3 | E571: =IF(C571="", "", IFERROR(VLOOKUP(C571, Price_List!A:D, IF(Dashboard!$B$9="樂觀(Snipe)", 3, IF(Dashboard!$B$9="悲觀(Panic)", 4, 2)), 0), 0)) -> 189998 | F571: =IF(C571="", "", D571*E571) -> 569994
E572: =IF(C572="", "", IFERROR(VLOOKUP(C572, Price_List!A:D, IF(Dashboard!$B$9="樂觀(Snipe)", 3, IF(Dashboard!$B$9="悲觀(Panic)", 4, 2)), 0), 0)) | F572: =IF(C572="", "", D572*E572)
E573: =IF(C573="", "", IFERROR(VLOOKUP(C573, Price_List!A:D, IF(Dashboard!$B$9="樂觀(Snipe)", 3, IF(Dashboard!$B$9="悲觀(Panic)", 4, 2)), 0), 0)) | F573: =IF(C573="", "", D573*E573)
E574: =IF(C574="", "", IFERROR(VLOOKUP(C574, Price_List!A:D, IF(Dashboard!$B$9="樂觀(Snipe)", 3, IF(Dashboard!$B$9="悲觀(Panic)", 4, 2)), 0), 0)) | F574: =IF(C574="", "", D574*E574)
E575: =IF(C575="", "", IFERROR(VLOOKUP(C575, Price_List!A:D, IF(Dashboard!$B$9="樂觀(Snipe)", 3, IF(Dashboard!$B$9="悲觀(Panic)", 4, 2)), 0), 0)) | F575: =IF(C575="", "", D575*E575)
E576: =IF(C576="", "", IFERROR(VLOOKUP(C576, Price_List!A:D, IF(Dashboard!$B$9="樂觀(Snipe)", 3, IF(Dashboard!$B$9="悲觀(Panic)", 4, 2)), 0), 0)) | F576: =IF(C576="", "", D576*E576)
E577: =IF(C577="", "", IFERROR(VLOOKUP(C577, Price_List!A:D, IF(Dashboard!$B$9="樂觀(Snipe)", 3, IF(Dashboard!$B$9="悲觀(Panic)", 4, 2)), 0), 0)) | F577: =IF(C577="", "", D577*E577)
E578: =IF(C578="", "", IFERROR(VLOOKUP(C578, Price_List!A:D, IF(Dashboard!$B$9="樂觀(Snipe)", 3, IF(Dashboard!$B$9="悲觀(Panic)", 4, 2)), 0), 0)) | F578: =IF(C578="", "", D578*E578)
E579: =IF(C579="", "", IFERROR(VLOOKUP(C579, Price_List!A:D, IF(Dashboard!$B$9="樂觀(Snipe)", 3, IF(Dashboard!$B$9="悲觀(Panic)", 4, 2)), 0), 0)) | F579: =IF(C579="", "", D579*E579)
E580: =IF(C580="", "", IFERROR(VLOOKUP(C580, Price_List!A:D, IF(Dashboard!$B$9="樂觀(Snipe)", 3, IF(Dashboard!$B$9="悲觀(Panic)", 4, 2)), 0), 0)) | F580: =IF(C580="", "", D580*E580)
E581: =IF(C581="", "", IFERROR(VLOOKUP(C581, Price_List!A:D, IF(Dashboard!$B$9="樂觀(Snipe)", 3, IF(Dashboard!$B$9="悲觀(Panic)", 4, 2)), 0), 0)) | F581: =IF(C581="", "", D581*E581)
E582: =IF(C582="", "", IFERROR(VLOOKUP(C582, Price_List!A:D, IF(Dashboard!$B$9="樂觀(Snipe)", 3, IF(Dashboard!$B$9="悲觀(Panic)", 4, 2)), 0), 0)) | F582: =IF(C582="", "", D582*E582)
E583: =IF(C583="", "", IFERROR(VLOOKUP(C583, Price_List!A:D, IF(Dashboard!$B$9="樂觀(Snipe)", 3, IF(Dashboard!$B$9="悲觀(Panic)", 4, 2)), 0), 0)) | F583: =IF(C583="", "", D583*E583)
... E899: =IF(C899="", "", IFERROR(VLOOKUP(C899, Price_List!A:D, IF(Dashboard!$B$9="樂觀(Snipe)", 3, IF(Dashboard!$B$9="悲觀(Panic)", 4, 2)), 0), 0)) | F899: =IF(C899="", "", D899*E899)
